<?xml version="1.0" encoding="utf-8"?>
<!-- This URDF was automatically created by SolidWorks to URDF Exporter! Originally created by Stephen Brawner (brawner@gmail.com) 
     Commit Version: 1.6.0-1-g15f4949  Build Version: 1.6.7594.29634
     For more information, please see http://wiki.ros.org/sw_urdf_exporter -->
<robot
  name="jaka_zu7_v2">
  <link
    name="base_link">
    <inertial>
      <origin
        xyz="0.000965034909848577 0.0195530292148323 -7.27080869111029E-08"
        rpy="0 0 0" />
      <mass
        value="0.514609969031532" />
      <inertia
        ixx="0.000621364399247646"
        ixy="3.21692650554867E-06"
        ixz="-3.71184934823013E-09"
        iyy="0.0013529358522947"
        iyz="3.8977685173265E-11"
        izz="0.00086645249213919" />
    </inertial>
    <visual>
      <origin
        xyz="0 0 0"
        rpy="0 0 0" />
      <geometry>
        <mesh
          filename="package://jaka_zu7_v2/meshes/base_link.STL" />
      </geometry>
      <material
        name="">
        <color
          rgba="1 1 1 1" />
      </material>
    </visual>
    <collision>
      <origin
        xyz="0 0 0"
        rpy="0 0 0" />
      <geometry>
        <mesh
          filename="package://jaka_zu7_v2/meshes/base_link.STL" />
      </geometry>
    </collision>
  </link>
  <link
    name="link_1">
    <inertial>
      <origin
        xyz="0.00332253130665769 0.0786385509598458 5.2958727998931E-08"
        rpy="0 0 0" />
      <mass
        value="1.92821258656447" />
      <inertia
        ixx="0.00548947482538057"
        ixy="1.93161087253844E-06"
        ixz="-2.06406149519604E-08"
        iyy="0.00388876051174381"
        iyz="-1.29468636322429E-08"
        izz="0.00564332197967477" />
    </inertial>
    <visual>
      <origin
        xyz="0 0 0"
        rpy="0 0 0" />
      <geometry>
        <mesh
          filename="package://jaka_zu7_v2/meshes/link_1.STL" />
      </geometry>
      <material
        name="">
        <color
          rgba="1 1 1 1" />
      </material>
    </visual>
    <collision>
      <origin
        xyz="0 0 0"
        rpy="0 0 0" />
      <geometry>
        <mesh
          filename="package://jaka_zu7_v2/meshes/link_1.STL" />
      </geometry>
    </collision>
  </link>
  <joint
    name="joint_1"
    type="continuous">
    <origin
      xyz="0 0 0.04"
      rpy="1.5707963267949 0 1.5707963267949" />
    <parent
      link="base_link" />
    <child
      link="link_1" />
    <axis
      xyz="0 1 0" />
  </joint>
  <link
    name="link_2">
    <inertial>
      <origin
        xyz="0.179999937405946 0.0790752745504925 9.75081933252131E-09"
        rpy="0 0 0" />
      <mass
        value="5.46179073513085" />
      <inertia
        ixx="0.0129179479280493"
        ixy="-2.71044464180044E-08"
        ixz="-1.50487643543411E-08"
        iyy="0.138149394009534"
        iyz="-2.73361042997731E-09"
        izz="0.141659548589032" />
    </inertial>
    <visual>
      <origin
        xyz="0 0 0"
        rpy="0 0 0" />
      <geometry>
        <mesh
          filename="package://jaka_zu7_v2/meshes/link_2.STL" />
      </geometry>
      <material
        name="">
        <color
          rgba="1 1 1 1" />
      </material>
    </visual>
    <collision>
      <origin
        xyz="0 0 0"
        rpy="0 0 0" />
      <geometry>
        <mesh
          filename="package://jaka_zu7_v2/meshes/link_2.STL" />
      </geometry>
    </collision>
  </link>
  <joint
    name="joint_2"
    type="continuous">
    <origin
      xyz="0.064 0.0801499805565675 0"
      rpy="-1.5707963267949 -1.5707963267949 0" />
    <parent
      link="link_1" />
    <child
      link="link_2" />
    <axis
      xyz="0 1 0" />
  </joint>
  <link
    name="link_3">
    <inertial>
      <origin
        xyz="0.155128159726302 0.0514243418134301 -2.21667684600496E-05"
        rpy="0 0 0" />
      <mass
        value="2.10988248004298" />
      <inertia
        ixx="0.00267097214313929"
        ixy="-0.00234320623456127"
        ixz="2.68932154375193E-07"
        iyy="0.0354758560218789"
        iyz="-5.66886998256416E-09"
        izz="0.0361345568869166" />
    </inertial>
    <visual>
      <origin
        xyz="0 0 0"
        rpy="0 0 0" />
      <geometry>
        <mesh
          filename="package://jaka_zu7_v2/meshes/link_3.STL" />
      </geometry>
      <material
        name="">
        <color
          rgba="1 1 1 1" />
      </material>
    </visual>
    <collision>
      <origin
        xyz="0 0 0"
        rpy="0 0 0" />
      <geometry>
        <mesh
          filename="package://jaka_zu7_v2/meshes/link_3.STL" />
      </geometry>
    </collision>
  </link>
  <joint
    name="joint_3"
    type="continuous">
    <origin
      xyz="0.36 0 0"
      rpy="3.14159265358979 0 0" />
    <parent
      link="link_2" />
    <child
      link="link_3" />
    <axis
      xyz="0 1 0" />
  </joint>
  <link
    name="link_4">
    <inertial>
      <origin
        xyz="0.0428277143121445 -0.00580000262750839 -2.15426459782009E-07"
        rpy="0 0 0" />
      <mass
        value="0.707389472258975" />
      <inertia
        ixx="0.00114244205941306"
        ixy="1.06377457242975E-05"
        ixz="-1.00655969113403E-08"
        iyy="0.000665673392092465"
        iyz="4.52474533922176E-09"
        izz="0.00117908344473012" />
    </inertial>
    <visual>
      <origin
        xyz="0 0 0"
        rpy="0 0 0" />
      <geometry>
        <mesh
          filename="package://jaka_zu7_v2/meshes/link_4.STL" />
      </geometry>
      <material
        name="">
        <color
          rgba="1 1 1 1" />
      </material>
    </visual>
    <collision>
      <origin
        xyz="0 0 0"
        rpy="0 0 0" />
      <geometry>
        <mesh
          filename="package://jaka_zu7_v2/meshes/link_4.STL" />
      </geometry>
    </collision>
  </link>
  <joint
    name="joint_4"
    type="continuous">
    <origin
      xyz="0.303500360870988 -0.00551249887704253 -2.30390977538769E-05"
      rpy="-1.5707963267949 0 -1.5707963267949" />
    <parent
      link="link_3" />
    <child
      link="link_4" />
    <axis
      xyz="1 0 0" />
  </joint>
  <link
    name="link_5">
    <inertial>
      <origin
        xyz="-0.0431572815381937 0.00288955773134447 1.49710568941863E-07"
        rpy="0 0 0" />
      <mass
        value="0.806937512326124" />
      <inertia
        ixx="0.0016178075971003"
        ixy="5.79122309605624E-06"
        ixz="-2.27237716815389E-08"
        iyy="0.000744722110552353"
        iyz="6.4924718539349E-10"
        izz="0.00165512070235347" />
    </inertial>
    <visual>
      <origin
        xyz="0 0 0"
        rpy="0 0 0" />
      <geometry>
        <mesh
          filename="package://jaka_zu7_v2/meshes/link_5.STL" />
      </geometry>
      <material
        name="">
        <color
          rgba="1 1 1 1" />
      </material>
    </visual>
    <collision>
      <origin
        xyz="0 0 0"
        rpy="0 0 0" />
      <geometry>
        <mesh
          filename="package://jaka_zu7_v2/meshes/link_5.STL" />
      </geometry>
    </collision>
  </link>
  <joint
    name="joint_5"
    type="continuous">
    <origin
      xyz="0.0455 -0.0680000000070426 0"
      rpy="3.14159265358979 0 1.5707963267949" />
    <parent
      link="link_4" />
    <child
      link="link_5" />
    <axis
      xyz="1 0 0" />
  </joint>
  <link
    name="link_6">
    <inertial>
      <origin
        xyz="-1.97890204940432E-05 -0.0177548861304407 2.35655774806776E-05"
        rpy="0 0 0" />
      <mass
        value="0.180494479521819" />
      <inertia
        ixx="9.15750415659571E-05"
        ixy="-3.15858980075031E-08"
        ixz="1.86044178570153E-07"
        iyy="0.000144413544278706"
        iyz="1.29636476465431E-07"
        izz="9.21528525921217E-05" />
    </inertial>
    <visual>
      <origin
        xyz="0 0 0"
        rpy="0 0 0" />
      <geometry>
        <mesh
          filename="package://jaka_zu7_v2/meshes/link_6.STL" />
      </geometry>
      <material
        name="">
        <color
          rgba="1 1 1 1" />
      </material>
    </visual>
    <collision>
      <origin
        xyz="0 0 0"
        rpy="0 0 0" />
      <geometry>
        <mesh
          filename="package://jaka_zu7_v2/meshes/link_6.STL" />
      </geometry>
    </collision>
  </link>
  <joint
    name="joint_6"
    type="continuous">
    <origin
      xyz="-0.0455 -0.0680000000070427 0"
      rpy="3.14159265358979 -1.15491803400099 -3.14159265358979" />
    <parent
      link="link_5" />
    <child
      link="link_6" />
    <axis
      xyz="0 1 0" />
  </joint>
</robot>
