<?xml version="1.0" ?>
<robot xmlns:xacro="http://www.ros.org/wiki/xacro" name="jakaUr">
  <xacro:property name="pi" value="3.14159265358"/>

  <material name="blue">
    <color rgba="0 0 0.8 1"/>
  </material>

  <material name="black">
    <color rgba="0 0 0 1"/>
  </material>

  <material name="white">
    <color rgba="1 1 1 1"/>
  </material>

  <!--   <link name="world">
      <origin rpy="0 0 0" xyz="0 0 -0.2"/>
  </link>
  <joint name="fixed" type="fixed"> -->
  <!--  <origin rpy="0 0 0" xyz="0 0 -0.8"/>
    <parent link="world"/>
    <child link="base_link"/>
  </joint> -->

  <!--  <joint name="bottom_joint" type="fixed">
    <origin xyz="0 0 0" rpy="0 0 0" />
    <parent link="base_link"/>
    <child link="bottom_link"/>
  </joint>

  <link name="bottom_link"> -->

  <!--visual>
      <origin xyz=" 0 0 -0.04" rpy="0 0 0"/>
      <geometry>

               <box size="1 1 0.02" />

      </geometry>
      <material name="Brown" />
    </visual>

    <collision>
      <origin xyz=" 0 0 -0.04" rpy="0 0 0"/>
      <geometry>
               <box size="1 1 0.02" />
      </geometry>
      </collision>-->
  <!--  <inertial>
      <mass value="5"/>
      <inertia ixx="0.2" ixy="0.0" ixz="0.0" iyy="0.2" iyz="0.0" izz="0.1"/>
    </inertial>


  </link> -->


  <link name="base_link">
    <visual>
      <!--origin rpy="0 ${pi / 2} 0" xyz="0 0 0.0198"/>-->
      <origin rpy="0 0 0" xyz="0 0 -0.0005"/>
      <geometry>
        <mesh filename="package://Zu7/mesh/p11.dae"/>
      </geometry>
      <material name="white">
        <color rgba="1 1 1 1"/>
      </material>
    </visual>

    <collision>
      <geometry>
        <mesh filename="package://Zu7/mesh/p11.dae"/>
      </geometry>
      <origin rpy="0 0 0" xyz="0 0 -0.0005"/>
    </collision>
    <!--inertial>
      <mass value="5"/>
      <inertia ixx="0.2" ixy="0.0" ixz="0.0" iyy="0.2" iyz="0.0" izz="0.1"/>
    </inertial-->

  </link>

  <link name="link_1">
    <visual>
      <geometry>
        <mesh filename="package://Zu7/mesh/p22.dae"/>
      </geometry>
      <material name="white">
        <color rgba="1 1 1 1"/>
      </material>
      <!--origin rpy=" ${pi/2.0}  0  ${pi/2.0}" xyz="0 0 0"/>-->
      <origin rpy=" 0  0  0" xyz="0 0 0"/>
    </visual>

    <collision>
      <geometry>
        <mesh filename="package://Zu7/mesh/p22.dae"/>
      </geometry>
      <origin rpy=" 0  0  0" xyz="0 0 0"/>
    </collision>

    <inertial>
      <mass value="8"/>
      <inertia ixx="0.3" ixy="0.0" ixz="0.0" iyy="0.3" iyz="0.0" izz="0.2"/>
    </inertial>
  </link>



  <joint name="joint_1" type="revolute">
    <axis xyz="0 0 1"/>
    <limit effort="1000" lower="-3.14159265358" upper="3.14159265358" velocity="0.5"/>
    <origin rpy="0 0 0" xyz="0 0 0.114"/>
    <parent link="base_link"/>
    <child link="link_1"/>
  </joint>

  <transmission name="joint_1_trans">
    <type>transmission_interface/SimpleTransmission</type>
    <actuator name="$joint_1_motor">
      <mechanicalReduction>1</mechanicalReduction>
    </actuator>
    <joint name="joint_1">
      <hardwareInterface>PositionJointInterface</hardwareInterface>
    </joint>
  </transmission>

  <link name="link_2">
    <visual>
      <geometry>
        <mesh filename="package://Zu7/mesh/p35.dae"/>
      </geometry>
      <!--origin rpy="${pi/2.0}  ${pi} ${pi/2.0}" xyz="-0.1595 0 -0.115"/>-->
      <material name="white">
        <color rgba="1 1 1 1"/>
      </material>
      <origin rpy="${pi/2.0} ${pi} ${pi/2.0}" xyz="0 0 0.01 "/>
      <material name="white">
        <color rgba="1 1 1 1"/>
      </material>
    </visual>

    <collision>
      <geometry>
        <mesh filename="package://Zu7/mesh/p35.dae"/>
      </geometry>
      <origin rpy="${pi/2.0} ${pi} ${pi/2.0}" xyz="0 0 0.01 "/>
    </collision>

    <inertial>
      <mass value="6"/>
      <inertia ixx="0.25" ixy="0.0" ixz="0.0" iyy="0.25" iyz="0.0" izz="0.15"/>
    </inertial>

  </link>



  <joint name="joint_2" type="revolute">
    <axis xyz="0 0 1"/>
    <limit effort="1000" lower="-3.14159265358" upper="3.14159265358" velocity="0.5"/>
    <origin rpy="${pi/2.0} 0 0" xyz="0 0.005 0"/>
    <parent link="link_1"/>
    <child link="link_2"/>
  </joint>

  <transmission name="joint_2_trans">
    <type>transmission_interface/SimpleTransmission</type>
    <actuator name="$joint_2_motor">
      <mechanicalReduction>1</mechanicalReduction>
    </actuator>
    <joint name="joint_2">
      <hardwareInterface>PositionJointInterface</hardwareInterface>
    </joint>
  </transmission>

  <link name="link_3">
    <visual>
      <geometry>
        <mesh filename="package://Zu7/mesh/p44.dae"/>
      </geometry>
      <material name="white">
        <color rgba="1 1 1 1"/>
      </material>
      <origin rpy="${-pi/2.0} 0 ${-pi/2.0}" xyz="0.303 0 -0.013"/>
    </visual>

    <collision>
      <geometry>
        <mesh filename="package://Zu7/mesh/p44.dae"/>
      </geometry>
      <origin rpy="${-pi/2.0} 0 ${-pi/2.0}" xyz="0.303 0 -0.013"/>
    </collision>

    <inertial>
      <mass value="8"/>
      <inertia ixx="0.3" ixy="0.0" ixz="0.0" iyy="0.3" iyz="0.0" izz="0.2"/>
    </inertial>

  </link>


  <joint name="joint_3" type="revolute">
    <axis xyz="0 0 1"/>
    <limit effort="1000" lower="-3.14159265358" upper="3.14159265358" velocity="0.5"/>
    <origin rpy="0 0 0" xyz="0.353 0 0.005"/>
    <parent link="link_2"/>
    <child link="link_3"/>
  </joint>

  <transmission name="joint_3_trans">
    <type>transmission_interface/SimpleTransmission</type>
    <actuator name="joint_3_motor">
      <mechanicalReduction>1</mechanicalReduction>
    </actuator>
    <joint name="joint_3">
      <hardwareInterface>PositionJointInterface</hardwareInterface>
    </joint>
  </transmission>

  <link name="link_4">
    <visual>
      <geometry>
        <mesh filename="package://Zu7/mesh/p55.dae"/>
      </geometry>
      <origin rpy="${pi/2.0} 0 ${pi/2.0}" xyz="0.00 0 0.00"/>
      <material name="white">
        <color rgba="1 1 1 1"/>
      </material>
    </visual>

    <collision>
      <geometry>
        <mesh filename="package://Zu7/mesh/p55.dae"/>
      </geometry>
      <origin rpy="${pi/2.0} 0 ${pi/2.0}" xyz="0.00 0 0.00"/>
    </collision>

    <inertial>
      <mass value="5"/>
      <inertia ixx="0.2" ixy="0.0" ixz="0.0" iyy="0.2" iyz="0.0" izz="0.15"/>
    </inertial>

  </link>


  <joint name="joint_4" type="revolute">
    <axis xyz="0 0 1"/>
    <limit effort="1000" lower="-3.14159265358" upper="3.14159265358" velocity="0.5"/>
    <origin rpy="0 0 0" xyz="0.303 0 -0.1155"/>
    <parent link="link_3"/>
    <child link="link_4"/>
  </joint>

  <transmission name="joint_4_trans">
    <type>transmission_interface/SimpleTransmission</type>
    <actuator name="joint_4_motor">
      <mechanicalReduction>1</mechanicalReduction>
    </actuator>
    <joint name="joint_4">
      <hardwareInterface>PositionJointInterface</hardwareInterface>
    </joint>
  </transmission>


  <link name="link_5">
    <visual>
      <geometry>
        <mesh filename="package://Zu7/mesh/p66.dae"/>
      </geometry>
      <origin rpy="${pi} 0 ${-pi/2.0}" xyz="0 0 0"/>
      <material name="white">
        <color rgba="1 1 1 1"/>
      </material>
    </visual>

    <collision>
      <geometry>
        <mesh filename="package://Zu7/mesh/p66.dae"/>
      </geometry>
      <origin rpy="${pi} 0 ${-pi/2.0}" xyz="0 0 0"/>
    </collision>

    <inertial>
      <mass value="4"/>
      <inertia ixx="0.1" ixy="0.0" ixz="0.0" iyy="0.1" iyz="0.0" izz="0.07"/>
    </inertial>

  </link>


  <joint name="joint_5" type="revolute">
    <axis xyz="0 0 1"/>
    <limit effort="1000" lower="-3.14159265358" upper="3.14159265358" velocity="0.5"/>
    <origin rpy="${pi/2.0} 0 0" xyz="0 -0.1025 0"/>
    <parent link="link_4"/>
    <child link="link_5"/>
  </joint>

  <transmission name="joint_5_trans">
    <type>transmission_interface/SimpleTransmission</type>
    <actuator name="joint_5_motor">
      <mechanicalReduction>1</mechanicalReduction>
    </actuator>
    <joint name="joint_5">
      <hardwareInterface>PositionJointInterface</hardwareInterface>
    </joint>
  </transmission>


  <link name="link_6">
    <visual>
      <geometry>
        <mesh filename="package://Zu7/mesh/p77.dae"/>
      </geometry>
      <origin rpy="0 ${-pi/2.0}  0" xyz="0 0 -0.0335"/>
    </visual>

    <collision>
      <geometry>
        <mesh filename="package://Zu7/mesh/p77.dae"/>
      </geometry>
      <origin rpy="0 ${-pi/2.0}  0" xyz="0 0 -0.0335"/>
    </collision>

    <inertial>
      <mass value="2"/>
      <inertia ixx="0.07" ixy="0.0" ixz="0.0" iyy="0.07" iyz="0.0" izz="0.04"/>
    </inertial>

  </link>


  <joint name="joint_6" type="revolute">
    <axis xyz="0 0 1"/>
    <limit effort="1000" lower="-3.14159265358" upper="3.14159265358" velocity="0.5"/>
    <origin rpy="${-pi/2.0} 0 0" xyz="0 0.093 0"/>
    <parent link="link_5"/>
    <child link="link_6"/>
  </joint>

  <transmission name="joint_6_trans">
    <type>transmission_interface/SimpleTransmission</type>
    <actuator name="joint_6_motor">
      <mechanicalReduction>1</mechanicalReduction>
    </actuator>
    <joint name="joint_6">
      <hardwareInterface>PositionJointInterface</hardwareInterface>
    </joint>
  </transmission>

  <!-- ros_control plugin -->
  <gazebo>
    <plugin name="gazebo_ros_control" filename="libgazebo_ros_control.so">
      <robotNamespace>/jakaUr</robotNamespace>
    </plugin>
  </gazebo>
</robot>
