<?xml version="1.0" ?>
<robot xmlns:xacro="http://www.ros.org/wiki/xacro" name="jakaUr">

  <xacro:macro name="jaka_robot" params="prefix">
    <xacro:property name="pi" value="3.14159265358979323846"/>


    <link name="${prefix}base_link">
      <visual>
        <!--origin rpy="0 ${pi / 2} 0" xyz="0 0 0.0198"/>-->
        <origin rpy="0 0 ${-pi/2}" xyz="0 0 -0.0005"/>
        <geometry>
          <mesh filename="package://zu7/mesh/p11.dae"/>
        </geometry>
        <material name="white">
          <color rgba="1 1 1 1"/>
        </material>
      </visual>

      <collision>
        <geometry>
          <mesh filename="package://zu7/mesh/p11.dae"/>
        </geometry>
        <origin rpy="0 0 0" xyz="0 0 -0.0005"/>
      </collision>
    </link>

    <link name="${prefix}link_1">
      <visual>
        <geometry>
          <mesh filename="package://zu7/mesh/p22.dae"/>
        </geometry>
        <material name="white">
          <color rgba="1 1 1 1"/>
        </material>
        <!--origin rpy=" ${pi/2.0}  0  ${pi/2.0}" xyz="0 0 0"/>-->
        <origin rpy="0 0 0" xyz="0 0 0"/>
      </visual>

      <collision>
        <geometry>
          <mesh filename="package://zu7/mesh/p22.dae"/>
        </geometry>
        <origin rpy="0 0 0" xyz="0 0 0"/>
      </collision>

      <inertial>
        <mass value="8"/>
        <inertia ixx="0.3" ixy="0.0" ixz="0.0" iyy="0.3" iyz="0.0" izz="0.2"/>
      </inertial>
    </link>

    <joint name="${prefix}joint_1" type="revolute">
      <axis xyz="0 0 1"/>
      <limit effort="1000" lower="-4.963716393" upper="4.963716393" velocity="3.14"/>
      <origin rpy="0 0 0" xyz="0 0 0.114"/>
      <parent link="${prefix}base_link"/>
      <child link="${prefix}link_1"/>
    </joint>


    <link name="${prefix}link_2">
      <visual>
        <geometry>
          <mesh filename="package://zu7/mesh/p35.dae"/>
        </geometry>
        <!--origin rpy="${pi/2.0}  ${pi} ${pi/2.0}" xyz="-0.1595 0 -0.115"/>-->
        <material name="white">
          <color rgba="1 1 1 1"/>
        </material>
        <origin rpy="${pi/2.0} ${pi} ${pi/2.0}" xyz="0 0 0.01 "/>
        <material name="white">
          <color rgba="1 1 1 1"/>
        </material>
      </visual>

      <collision>
        <geometry>
          <mesh filename="package://zu7/mesh/p35.dae"/>
        </geometry>
        <origin rpy="${pi/2.0} ${pi} ${pi/2.0}" xyz="0 0 0.01 "/>
      </collision>

      <inertial>
        <mass value="6"/>
        <inertia ixx="0.25" ixy="0.0" ixz="0.0" iyy="0.25" iyz="0.0" izz="0.15"/>
      </inertial>
    </link>

    <joint name="${prefix}joint_2" type="revolute">
      <axis xyz="0 0 1"/>
      <limit effort="1000" lower="-1.171988593" upper="3.653846789" velocity="3.14"/>
      <origin rpy="${pi/2.0} 0 0" xyz="0 0.005 0"/>
      <parent link="${prefix}link_1"/>
      <child link="${prefix}link_2"/>
    </joint>


    <link name="${prefix}link_3">
      <visual>
        <geometry>
          <mesh filename="package://zu7/mesh/p44.dae"/>
        </geometry>
        <material name="white">
          <color rgba="1 1 1 1"/>
        </material>
        <origin rpy="${-pi/2.0} 0 ${-pi/2.0}" xyz="0.303 0 -0.013"/>
      </visual>

      <collision>
        <geometry>
          <mesh filename="package://zu7/mesh/p44.dae"/>
        </geometry>
        <origin rpy="${-pi/2.0} 0 ${-pi/2.0}" xyz="0.303 0 -0.013"/>
      </collision>

      <inertial>
        <mass value="8"/>
        <inertia ixx="0.3" ixy="0.0" ixz="0.0" iyy="0.3" iyz="0.0" izz="0.2"/>
      </inertial>
    </link>

    <joint name="${prefix}joint_3" type="revolute">
      <axis xyz="0 0 1"/>
      <limit effort="1000" lower="-2.412917691" upper="2.412917691" velocity="3.14"/>
      <origin rpy="0 0 0" xyz="0.353 0 0.005"/>
      <parent link="${prefix}link_2"/>
      <child link="${prefix}link_3"/>
    </joint>


    <link name="${prefix}link_4">
      <visual>
        <geometry>
          <mesh filename="package://zu7/mesh/p55.dae"/>
        </geometry>
        <origin rpy="${pi/2.0} 0 ${pi/2.0}" xyz="0.00 0 0.00"/>
        <material name="white">
          <color rgba="1 1 1 1"/>
        </material>
      </visual>

      <collision>
        <geometry>
          <mesh filename="package://zu7/mesh/p55.dae"/>
        </geometry>
        <origin rpy="${pi/2.0} 0 ${pi/2.0}" xyz="0.00 0 0.00"/>
      </collision>

      <inertial>
        <mass value="5"/>
        <inertia ixx="0.2" ixy="0.0" ixz="0.0" iyy="0.2" iyz="0.0" izz="0.15"/>
      </inertial>
    </link>

    <joint name="${prefix}joint_4" type="revolute">
      <axis xyz="0 0 1"/>
      <limit effort="1000" lower="-1.171988593" upper="3.653846789" velocity="3.14"/>
      <origin rpy="0 0 0" xyz="0.303 0 -0.1155"/>
      <parent link="${prefix}link_3"/>
      <child link="${prefix}link_4"/>
    </joint>


    <link name="${prefix}link_5">
      <visual>
        <geometry>
          <mesh filename="package://zu7/mesh/p66.dae"/>
        </geometry>
        <origin rpy="${pi} 0 ${-pi/2.0}" xyz="0 0 0"/>
        <material name="">
          <color rgba="1 0.1 0.1 1"/>
        </material>
      </visual>

      <collision>
        <geometry>
          <mesh filename="package://zu7/mesh/p66.dae"/>
        </geometry>
        <origin rpy="${pi} 0 ${-pi/2.0}" xyz="0 0 0"/>
      </collision>

      <inertial>
        <mass value="4"/>
        <inertia ixx="0.1" ixy="0.0" ixz="0.0" iyy="0.1" iyz="0.0" izz="0.07"/>
      </inertial>
    </link>

    <joint name="${prefix}joint_5" type="revolute">
      <axis xyz="0 0 1"/>
      <limit effort="1000" lower="-4.963716393" upper="4.963716393" velocity="3.14"/>
      <origin rpy="${pi/2.0} 0 0" xyz="0 -0.1025 0"/>
      <parent link="${prefix}link_4"/>
      <child link="${prefix}link_5"/>
    </joint>


    <link name="${prefix}link_6">
      <visual>
        <geometry>
          <mesh filename="package://zu7/mesh/p77.dae"/>
        </geometry>
        <origin rpy="0 ${-pi/2.0} 0" xyz="0 0 0"/>
      </visual>

      <collision>
        <geometry>
          <mesh filename="package://zu7/mesh/p77.dae"/>
        </geometry>
        <origin rpy="0 ${-pi/2.0} 0" xyz="0 0 0"/>
      </collision>

      <inertial>
        <mass value="2"/>
        <inertia ixx="0.07" ixy="0.0" ixz="0.0" iyy="0.07" iyz="0.0" izz="0.04"/>
      </inertial>
    </link>


    <joint name="${prefix}joint_6" type="revolute">
      <axis xyz="0 0 1"/>
      <limit effort="1000" lower="-4.963716393" upper="4.963716393" velocity="3.14"/>
      <origin rpy="${-pi/2.0} 0 0" xyz="0 0.0595 0"/>
      <parent link="${prefix}link_5"/>
      <child link="${prefix}link_6"/>
    </joint>

  </xacro:macro>
</robot>
